<?xml version="1.0"?>
<robot name="paintingrobot" xmlns:xacro="http://www.ros.org/wiki/xacro">

  <!-- PROPERTY LIST -->
    <xacro:property name="M_PI" value="3.1415926"/>
	
	
 <!-- Macro for inertia matrix -->
    <xacro:macro name="sphere_inertial_matrix" params="m r">
        <inertial>
            <mass value="${m}" />
            <inertia ixx="${2*m*r*r/5}" ixy="0" ixz="0"
                iyy="${2*m*r*r/5}" iyz="0" 
                izz="${2*m*r*r/5}" />
        </inertial>
    </xacro:macro>

    <xacro:macro name="cylinder_inertial_matrix" params="m r h">
        <inertial>
            <mass value="${m}" />
            <inertia ixx="${m*(3*r*r+h*h)/12}" ixy = "0" ixz = "0"
                iyy="${m*(3*r*r+h*h)/12}" iyz = "0"
                izz="${m*r*r/2}" /> 
        </inertial>
    </xacro:macro> 

    <xacro:macro name="cuboid_inertial" params="length weight hight mass *origin">
      <inertial>
        <mass value="${mass}" />
        <xacro:insert_block name="origin" />
        <inertia ixx="${0.0833333 * mass * (length * length + hight * hight)}" ixy="0.0" ixz="0.0"
                iyy="${0.0833333 * mass * ( weight * weight + hight * hight)}" iyz="0.0"
                izz="${0.0833333 * mass * ( length * length + weight * weight)}" />
      </inertial>
    </xacro:macro>

 <!-- robot -->
<xacro:macro name="paintingrobot" params="prefix:=paintingrobot">	

  <link
    name="base_link">
    <inertial>
      <origin
        xyz="-9.74542958129844E-19 -8.30827569009276E-50 0.01"
        rpy="0 0 0" />
      <mass
        value="0.15707963267949" />
      <inertia
        ixx="0.000103410758180664"
        ixy="-2.44698917549945E-52"
        ixz="1.99868489765398E-36"
        iyy="0.000103410758180664"
        iyz="-1.5177569000538E-37"
        izz="0.000196349540849362" />
    </inertial>
    <visual>
      <origin
        xyz="0 0 0"
        rpy="0 0 0" />
      <geometry>
        <mesh
          filename="package://paintingrobot_description/meshes/base_link.STL" />
      </geometry>
      <material
        name="">
        <color
          rgba="1 1 1 1" />
      </material>
    </visual>
  </link>
  <link
    name="base_link2">
    <inertial>
      <origin
        xyz="-9.74542958129844E-19 -8.30827569009276E-50 0.01"
        rpy="0 0 0" />
      <mass
        value="0.15707963267949" />
      <inertia
        ixx="0.000103410758180664"
        ixy="-2.44698917549945E-52"
        ixz="1.99868489765398E-36"
        iyy="0.000103410758180664"
        iyz="-1.5177569000538E-37"
        izz="0.000196349540849362" />
    </inertial>

    <visual>
      <origin
        xyz="0 0 0"
        rpy="0 0 0" />
      <geometry>
        <mesh
          filename="package://paintingrobot_description/meshes/base_link2.STL" />
      </geometry>
      <material
        name="">
        <color
          rgba="1 1 1 1" />
      </material>
    </visual>
  </link>
  <joint
    name="base_joint1"
    type="prismatic">
    <origin
      xyz="0 0 -0.06"
      rpy="0 0 0" />
    <parent
      link="base_link" />
    <child
      link="base_link2" />
    <axis
      xyz="1 0 0" />
    <limit
      lower="-1000"
      upper="1000"
      effort="50000"
      velocity="10" />
  </joint>
  <link
    name="base_link3">
    <inertial>
      <origin
        xyz="-9.74542958129844E-19 1.66165513801855E-49 0.01"
        rpy="0 0 0" />
      <mass
        value="0.15707963267949" />
      <inertia
        ixx="0.000103410758180664"
        ixy="5.3018098802488E-52"
        ixz="-3.37516786865257E-36"
        iyy="0.000103410758180664"
        iyz="-1.5177569000538E-37"
        izz="0.000196349540849362" />
    </inertial>

    <visual>
      <origin
        xyz="0 0 0"
        rpy="0 0 0" />
      <geometry>
        <mesh
          filename="package://paintingrobot_description/meshes/base_link3.STL" />
      </geometry>
      <material
        name="">
        <color
          rgba="1 1 1 1" />
      </material>
    </visual>
  </link>
  <joint
    name="base_joint2"
    type="prismatic">
    <origin
      xyz="0 0 -0.06"
      rpy="0 0 0" />
    <parent
      link="base_link2" />
    <child
      link="base_link3" />
    <axis
      xyz="0 -1 0" />
    <limit
      lower="-1000"
      upper="1000"
      effort="50000"
      velocity="10" />
  </joint>
  <link
    name="mobilebase_link">
    <inertial>
      <origin
        xyz="0.0291577665599809 -2.72164924299828E-07 0.441881950379727"
        rpy="0 0 0" />
      <mass
        value="455.358981535307" />
      <inertia
        ixx="44.9136198387836"
        ixy="3.50536725170582E-05"
        ixz="-1.212192154451"
        iyy="57.9677287950582"
        iyz="4.67729419428261E-05"
        izz="41.3161598074795" />
    </inertial>

    <visual>
      <origin
        xyz="0 0 0"
        rpy="0 0 0" />
      <geometry>
        <mesh
          filename="package://paintingrobot_description/meshes/mobilebase_link.STL" />
      </geometry>
      <material
        name="">
        <color
          rgba="0.792156862745098 0.819607843137255 0.933333333333333 1" />
      </material>
    </visual>
    <collision>
      <origin
        xyz="0 0 0"
        rpy="0 0 0" />
      <geometry>
        <mesh
          filename="package://paintingrobot_description/meshes/mobilebase_link.STL" />
      </geometry>
    </collision>
  </link>
  <joint
    name="mobilebase_joint"
    type="revolute">
    <origin
      xyz="0 0 0.195"
      rpy="0 0 0" />
    <parent
      link="base_link3" />
    <child
      link="mobilebase_link" />
    <axis
      xyz="0 0 1" />
    <limit
      lower="-3.2"
      upper="3.2"
      effort="50000"
      velocity="10" />
  </joint>
  <link
    name="rod_link">
    <inertial>
      <origin
        xyz="0 -6.22346643472761E-19 2.19372384937239"
        rpy="0 0 0" />
      <mass
        value="16.8939144946791" />
      <inertia
        ixx="27.0505138248194"
        ixy="-9.98342727444939E-35"
        ixz="2.5578757073893E-32"
        iyy="27.0505138248194"
        iyz="-1.46464356458114E-17"
        izz="0.0113194528551953" />
    </inertial>
    <visual>
      <origin
        xyz="0 0 0"
        rpy="0 0 0" />
      <geometry>
        <mesh
          filename="package://paintingrobot_description/meshes/rod_link.STL" />
      </geometry>
      <material
        name="">
        <color
          rgba="1 0.768627450980392 0.529411764705882 1" />
      </material>
    </visual>
    <collision>
      <origin
        xyz="0 0 0"
        rpy="0 0 0" />
      <geometry>
        <mesh
          filename="package://paintingrobot_description/meshes/rod_link.STL" />
      </geometry>
    </collision>
  </link>
  <joint
    name="rod_joint"
    type="fixed">
    <origin
      xyz="0.055 0 0"
      rpy="0 0 0" />
    <parent
      link="mobilebase_link" />
    <child
      link="rod_link" />
    <axis
      xyz="0 0 0" />
  </joint>
  <link
    name="rodclimbing_link1">
    <inertial>
      <origin
        xyz="6.93889390390723E-18 7.42122137321897E-18 0.0180768324845659"
        rpy="0 0 0" />
      <mass
        value="18.5984843965627" />
      <inertia
        ixx="0.326720473611573"
        ixy="2.29228291350695E-17"
        ixz="5.27407769936995E-18"
        iyy="0.50578957745673"
        iyz="3.37798961929826E-18"
        izz="0.240649696019101" />
    </inertial>
    <visual>
      <origin
        xyz="0 0 0"
        rpy="0 0 0" />
      <geometry>
        <mesh
          filename="package://paintingrobot_description/meshes/rodclimbing_link1.STL" />
      </geometry>
      <material
        name="">
        <color
          rgba="1 0.768627450980392 0.529411764705882 1" />
      </material>
    </visual>
    <collision>
      <origin
        xyz="0 0 0"
        rpy="0 0 0" />
      <geometry>
        <mesh
          filename="package://paintingrobot_description/meshes/rodclimbing_link1.STL" />
      </geometry>
    </collision>
  </link>
  <joint
    name="rodclimbing_joint1"
    type="prismatic">
    <origin
      xyz="0 0 1.2119"
      rpy="0 0 0" />
    <parent
      link="rod_link" />
    <child
      link="rodclimbing_link1" />
    <axis
      xyz="0 0 1" />
    <limit
      lower="-0.5"
      upper="3.5"
      effort="5000"
      velocity="10" />
  </joint>
  <link
    name="rodclimbing_link2">
    <inertial>
      <origin
        xyz="0.198799177954796 2.14617838848648E-17 0.021698767433032"
        rpy="0 0 0" />
      <mass
        value="3.80486871498238" />
      <inertia
        ixx="0.119326861165646"
        ixy="1.72526734960407E-18"
        ixz="0.000187142864467349"
        iyy="0.160129816052835"
        iyz="-2.22753887319819E-18"
        izz="0.0532964184778594" />
    </inertial>
    <visual>
      <origin
        xyz="0 0 0"
        rpy="0 0 0" />
      <geometry>
        <mesh
          filename="package://paintingrobot_description/meshes/rodclimbing_link2.STL" />
      </geometry>
      <material
        name="">
        <color
          rgba="1 0.768627450980392 0.529411764705882 1" />
      </material>
    </visual>
    <collision>
      <origin
        xyz="0 0 0"
        rpy="0 0 0" />
      <geometry>
        <mesh
          filename="package://paintingrobot_description/meshes/rodclimbing_link2.STL" />
      </geometry>
    </collision>
  </link>
  <joint
    name="rodclimbing_joint2"
    type="revolute">
    <origin
      xyz="0 0 0"
      rpy="0 0 0" />
    <parent
      link="rodclimbing_link1" />
    <child
      link="rodclimbing_link2" />
    <axis
      xyz="0 0 1" />
    <limit
      lower="-1.58"
      upper="3.2"
      effort="5000"
      velocity="10" />
  </joint>
  <link
    name="aubo_baselink">
    <inertial>
      <origin
        xyz="5.39350203387912E-09 -0.0001896424631547 0.0164378389040267"
        rpy="0 0 0" />
      <mass
        value="0.549895435681136" />
      <inertia
        ixx="0.0011097760848736"
        ixy="-1.38075248072163E-11"
        ixz="4.71554439639399E-13"
        iyy="0.00111737670773042"
        iyz="-1.26734365592631E-05"
        izz="0.00206099321499423" />
    </inertial>
    <visual>
      <origin
        xyz="0 0 0"
        rpy="0 0 0" />
      <geometry>
        <mesh
          filename="package://paintingrobot_description/meshes/manipulatorbase_link.STL" />
      </geometry>
      <material
        name="">
        <color
          rgba="0.752941176470588 0.752941176470588 0.752941176470588 1" />
      </material>
    </visual>
    <collision>
      <origin
        xyz="0 0 0"
        rpy="0 0 0" />
      <geometry>
        <mesh
          filename="package://paintingrobot_description/meshes/manipulatorbase_link.STL" />
      </geometry>
    </collision>
  </link>
  <joint
    name="manipulatorbase_joint"
    type="fixed">
    <origin
      xyz="0.3757 -0.00033749 0.028625"
      rpy="0 0 0" />
    <parent
      link="rodclimbing_link2" />
    <child
      link="aubo_baselink" />
    <axis
      xyz="0 0 0" />
  </joint>


  <link name="shoulder_Link">
    <inertial>
      <origin xyz="3.2508868974735E-07 0.00534955349296065 -0.00883689325611056" rpy="0 0 0" />
      <mass value="1.57658348693929" />
      <inertia ixx="0.0040640448663128" ixy="0" ixz="0" iyy="0.00392863238466817" iyz="-0.000160151642851425" izz="0.0030869857349184" />
    </inertial>
    <visual>
      <origin xyz="0 0 0" rpy="0 0 0" />
      <geometry>
        <mesh filename="package://paintingrobot_description/meshes/aubo_i5/visual/shoulder_Link.DAE" />
      </geometry>
      <material name="">
        <color rgba="1 1 1 1" />
      </material>
    </visual>
    <collision>
      <origin xyz="0 0 0" rpy="0 0 0" />
      <geometry>
        <mesh filename="package://paintingrobot_description/meshes/aubo_i5/collision/shoulder_Link.STL" />
      </geometry>
    </collision>
  </link>

  <joint name="shoulder_joint" type="revolute">
    <origin xyz="0 0 0.122" rpy="0 0 3.1416" />
    <parent link="aubo_baselink" />
    <child link="shoulder_Link" />
    <axis xyz="0 0 1" />
    <limit lower="-3.05" upper="3.05" effort="100" velocity="10" />
  </joint>

  <link name="upperArm_Link">
    <inertial>
      <origin xyz="0.203996646979614 2.01304585036544E-10 0.0127641545395984" rpy="0 0 0" />
      <mass value="4.04175782265494" />
      <inertia ixx="0.00965399211106204" ixy="0" ixz="0" iyy="0.144993869035655" iyz="0" izz="0.142607184038966" />
    </inertial>
    <visual>
      <origin xyz="0 0 0" rpy="0 0 0" />
      <geometry>
        <mesh filename="package://paintingrobot_description/meshes/aubo_i5/visual/upperArm_Link.DAE" />
      </geometry>
      <material name="">
        <color rgba="1 1 1 1" />
      </material>
    </visual>
    <collision>
      <origin xyz="0 0 0" rpy="0 0 0" />
      <geometry>
        <mesh filename="package://paintingrobot_description/meshes/aubo_i5/collision/upperArm_Link.STL" />
      </geometry>
    </collision>
  </link>

  <joint name="upperArm_joint" type="revolute">
    <origin xyz="0 0.1215 0" rpy="-1.5708 -1.5708 0" />
    <parent link="shoulder_Link" />
    <child link="upperArm_Link" />
    <axis xyz="0 0 1" />
    <limit lower="-3.05" upper="3.05" effort="1000" velocity="10" />
  </joint>

  <link name="foreArm_Link">
    <inertial>
      <origin xyz="0.188922115560337 6.78882434739072E-07 0.0981026740461557" rpy="0 0 0" />
      <mass  value="2.27145669098343" />
      <inertia ixx="0.00214322284946289" ixy="0" ixz="-0.00073120631553383" iyy="0.0443926090878205" iyz="0" izz="0.0441273797128365" />
    </inertial>
    <visual>
      <origin xyz="0 0 0" rpy="0 0 0" />
      <geometry>
        <mesh filename="package://paintingrobot_description/meshes/aubo_i5/visual/foreArm_Link.DAE" />
      </geometry>
      <material name="">
        <color rgba="1 1 1 1" />
      </material>
    </visual>
    <collision>
      <origin xyz="0 0 0" rpy="0 0 0" />
      <geometry>
        <mesh filename="package://paintingrobot_description/meshes/aubo_i5/collision/foreArm_Link.STL" />
      </geometry>
    </collision>
  </link>

  <joint name="foreArm_joint" type="revolute">
    <origin xyz="0.408 0 0" rpy="-3.1416 -5.1632E-18 -5.459E-16" />
    <parent link="upperArm_Link" />
    <child link="foreArm_Link" />
    <axis xyz="0 0 1" />
    <limit lower="-3.05" upper="3.05" effort="1000" velocity="10" />
  </joint>

  <link name="wrist1_Link">
    <inertial>
      <origin xyz="7.54205137428592E-07 0.0062481254331257 -0.00392367464072373" rpy="0 0 0" />
      <mass value="0.500477539188764" />
      <inertia ixx="0.00071194605962081" ixy="0" ixz="0" iyy="0.00040588242872958" iyz="-2.30808694377512E-05" izz="0.000685574004861334" />
    </inertial>
    <visual>
      <origin xyz="0 0 0" rpy="0 0 0" />
      <geometry>
        <mesh filename="package://paintingrobot_description/meshes/aubo_i5/visual/wrist1_Link.DAE" />
      </geometry>
      <material name="">
        <color rgba="1 1 1 1" />
      </material>
    </visual>
    <collision>
      <origin xyz="0 0 0" rpy="0 0 0" />
      <geometry>
        <mesh filename="package://paintingrobot_description/meshes/aubo_i5/collision/wrist1_Link.STL" />
      </geometry>
    </collision>
  </link>

  <joint name="wrist1_joint" type="revolute">
    <origin xyz="0.376 0 0" rpy="3.1416 -1.8323E-15 1.5708" />
    <parent link="foreArm_Link" />
    <child link="wrist1_Link" />
    <axis xyz="0 0 1" />
    <limit lower="-3.05" upper="3.05" effort="1000" velocity="10" />
  </joint>

  <link name="wrist2_Link">
    <inertial>
      <origin xyz="-7.54207620578635E-07 -0.00624812542617262 -0.00392367464115684" rpy="0 0 0" />
      <mass value="0.500477539245988" />
      <inertia ixx="0.00071194605981829" ixy="0" ixz="0" iyy="0.000405882428755442" iyz="2.30808694515886E-05" izz="0.000685574005112107" />
    </inertial>
    <visual>
      <origin xyz="0 0 0" rpy="0 0 0" />
      <geometry>
        <mesh filename="package://paintingrobot_description/meshes/aubo_i5/visual/wrist2_Link.DAE" />
      </geometry>
      <material name="">
        <color rgba="1 1 1 1" />
      </material>
    </visual>
    <collision>
      <origin xyz="0 0 0" rpy="0 0 0" />
      <geometry>
        <mesh filename="package://paintingrobot_description/meshes/aubo_i5/collision/wrist2_Link.STL" />
      </geometry>
    </collision>
  </link>

  <joint name="wrist2_joint" type="revolute">
    <origin xyz="0 0.1025 0" rpy="-1.5708 -1.8709E-15 -1.6653E-16" />
    <parent link="wrist1_Link" />
    <child link="wrist2_Link" />
    <axis xyz="0 0 1" />
    <limit lower="-3.05" upper="3.05" effort="1000" velocity="10" />
  </joint>

  <link name="wrist3_Link">
    <inertial>
      <origin xyz="3.92048778449938E-10 0.000175788057281467 -0.0213294490706684" rpy="0 0 0" />
      <mass value="0.158309554874285" />
      <inertia ixx="7.31376196034769E-05" ixy="0" ixz="0" iyy="7.19528188876563E-05" iyz="0" izz="0.000108772439051422" />
    </inertial>
    <visual>
      <origin xyz="0 0 0" rpy="0 0 0" />
      <geometry>
        <mesh filename="package://paintingrobot_description/meshes/aubo_i5/visual/wrist3_Link.DAE" />
      </geometry>
      <material name="">
        <color rgba="1 1 1 1" />
      </material>
    </visual>
    <collision>
      <origin xyz="0 0 0" rpy="0 0 0" />
      <geometry>
        <mesh filename="package://paintingrobot_description/meshes/aubo_i5/collision/wrist3_Link.STL" />
      </geometry>
    </collision>
  </link>

  <joint name="wrist3_joint" type="revolute">
    <origin xyz="0 -0.094 0" rpy="1.5708 0 1.7907E-15" />
    <parent link="wrist2_Link" />
    <child link="wrist3_Link" />
    <axis xyz="0 0 1" />
    <limit lower="-3.05" upper="3.05" effort="1000" velocity="10" />
  </joint>


<!-- Transmissions for ROS Control -->
  <xacro:macro name="transmission_block" params="joint_name">
    <transmission name="tran_${joint_name}">
      <type>transmission_interface/SimpleTransmission</type>
      <joint name="${joint_name}">
        <hardwareInterface>hardware_interface/PositionJointInterface</hardwareInterface>
      </joint>
      <actuator name="motor_${joint_name}">
        <hardwareInterface>hardware_interface/PositionJointInterface</hardwareInterface>
        <mechanicalReduction>1</mechanicalReduction>
      </actuator>
    </transmission>
  </xacro:macro>

  <xacro:transmission_block joint_name="base_joint1"/>
  <xacro:transmission_block joint_name="base_joint2"/>
  <xacro:transmission_block joint_name="mobilebase_joint"/>
  <xacro:transmission_block joint_name="rodclimbing_joint1"/>
  <xacro:transmission_block joint_name="rodclimbing_joint2"/>
  <xacro:transmission_block joint_name="shoulder_joint"/>
  <xacro:transmission_block joint_name="upperArm_joint"/>
  <xacro:transmission_block joint_name="foreArm_joint"/>
  <xacro:transmission_block joint_name="wrist1_joint"/>
  <xacro:transmission_block joint_name="wrist2_joint"/>
  <xacro:transmission_block joint_name="wrist3_joint"/>


<!-- ros_control plugin -->
    <gazebo>
        <plugin name="gazebo_ros_control" filename="libgazebo_ros_control.so">
            <robotNamespace>/paintingrobot</robotNamespace>
            <robotSimType>gazebo_ros_control/DefaultRobotHWSim</robotSimType>
            <legacyModeNS>true</legacyModeNS>
        </plugin>
    </gazebo>

    <!-- position controller -->
    <gazebo>
      <plugin name="base_controller" filename="libgazebo_ros_planar_move.so">
        <commandTopic>cmd_vel</commandTopic>
        <odometryTopic>odom</odometryTopic>
        <odometryFrame>/odom</odometryFrame>
        <odometryRate>100.0</odometryRate>
        <robotBaseFrame>base_footprint</robotBaseFrame>
        <broadcastTF>true</broadcastTF>
      </plugin>
    </gazebo>

    <gazebo reference="base_footprint">
      <turnGravityOff>true</turnGravityOff>
    </gazebo>
    <gazebo reference="base_link">
      <turnGravityOff>true</turnGravityOff>
    </gazebo>
    <gazebo reference="base_link2">
      <turnGravityOff>true</turnGravityOff>
    </gazebo>
    <gazebo reference="base_link3">
      <turnGravityOff>true</turnGravityOff>
    </gazebo>
    <gazebo reference="mobilebase_link">
      <turnGravityOff>true</turnGravityOff>
    </gazebo>
    <gazebo reference="rod_link">
      <turnGravityOff>true</turnGravityOff>
    </gazebo>
    <gazebo reference="rodclimbing_link1">
      <turnGravityOff>true</turnGravityOff>
    </gazebo>
    <gazebo reference="rodclimbing_link2">
      <turnGravityOff>true</turnGravityOff>
    </gazebo>
    <gazebo reference="aubo_baselink">
      <turnGravityOff>true</turnGravityOff>
    </gazebo>
    <gazebo reference="shoulder_Link">
      <turnGravityOff>true</turnGravityOff>
    </gazebo>
    <gazebo reference="upperArm_Link">
      <turnGravityOff>true</turnGravityOff>
    </gazebo>
    <gazebo reference="foreArm_Link">
      <turnGravityOff>true</turnGravityOff>
    </gazebo>
    <gazebo reference="wrist1_Link">
      <turnGravityOff>true</turnGravityOff>
    </gazebo>
    <gazebo reference="wrist2_Link">
      <turnGravityOff>true</turnGravityOff>
    </gazebo>
    <gazebo reference="wrist3_Link">
      <turnGravityOff>true</turnGravityOff>
    </gazebo>
    <gazebo reference="zed_camera_center">
      <turnGravityOff>true</turnGravityOff>
    </gazebo>
    <gazebo reference="zed_frame_optical">
      <turnGravityOff>true</turnGravityOff>
    </gazebo>
    <gazebo reference="kinect_link">
      <turnGravityOff>true</turnGravityOff>
    </gazebo>
    <gazebo reference="kinect_frame_optical">
      <turnGravityOff>true</turnGravityOff>
    </gazebo>
    <gazebo reference="laser_link">
      <turnGravityOff>true</turnGravityOff>
    </gazebo>


</xacro:macro>
</robot>